<mujoco model="sawyer">
    <compiler angle="radian" />
    <size njmax="500" nconmax="100" />
    <worldbody>
        <geom size="0.18 0.31" pos="0 0 -0.3" type="cylinder" rgba="0.2 0.2 0.2 1" />
        <geom size="0.08 0.12" pos="0 0 0.12" type="cylinder" rgba="0.5 0.1 0.1 1" />
        <body name="right_l0" pos="0 0 0.08">
            <inertial pos="0.0243645 0.0109688 0.143631" quat="0.894821 0.0089945 -0.17028 0.412576" mass="5.3214" diaginertia="0.0651599 0.0510954 0.0186221" />
            <joint name="right_j0" pos="0 0 0" axis="0 0 1" limited="true" range="-3.0503 3.0503" />
            <geom size="0.07" pos="0.081 0 0.237" rgba="0.5 0.1 0.1 1" />
            <body name="head" pos="0 0 0.2965">
                <inertial pos="0.00532337 -2.65456e-05 0.102107" quat="0.999993 7.07353e-05 -0.00358293 -0.000626283" mass="1.5797" diaginertia="0.0118347 0.00827232 0.00496586" />
                <joint name="head_pan" pos="0 0 0" axis="0 0 1" limited="true" range="-5.1477 0.9559" />
                <geom size="0.18" pos="0 0 0.08" rgba="0.5 0.1 0.1 1" />
                <geom size="0.001" pos="0.03 0 0.105" quat="0.499998 0.5 0.500002 0.5" rgba="0.2 0.2 0.2 1" />
            </body>
            <body name="right_l1" pos="0.081 0.05 0.237" quat="0.499998 -0.5 0.5 0.500002">
                <inertial pos="-0.0030849 -0.026811 0.092521" quat="0.424888 0.891987 0.132364 -0.0794296" mass="4.505" diaginertia="0.0224339 0.0221624 0.0097097" />
                <joint name="right_j1" pos="0 0 0" axis="0 0 1" limited="true" range="-3.8183 2.2824" />
                <geom size="0.07" pos="0 0 0.1225" rgba="0.5 0.1 0.1 1" />
                <body name="right_l2" pos="0 -0.14 0.1425" quat="0.707105 0.707108 0 0">
                    <inertial pos="-0.00016232 -0.015346 0.13445" quat="0.707249 -0.0541564 0.0533441 0.702866" mass="1.7251" diaginertia="0.0255023 0.025176 0.00285946" />
                    <joint name="right_j2" pos="0 0 0" axis="0 0 1" limited="true" range="-3.0514 3.0514" />
                    <geom size="0.06 0.175" pos="0 0 0.14" type="cylinder" rgba="0.5 0.1 0.1 1" />
                    <body name="right_l3" pos="0 -0.042 0.26" quat="0.707105 -0.707108 0 0">
                        <inertial pos="-0.0046678 -0.028394 -0.083127" quat="0.894367 0.380888 -0.106513 0.209016" mass="2.4743" diaginertia="0.0100572 0.00959393 0.00350313" />
                        <joint name="right_j3" pos="0 0 0" axis="0 0 1" limited="true" range="-3.0514 3.0514" />
                        <geom size="0.06" pos="0 -0.01 -0.12" rgba="0.5 0.1 0.1 1" />
                        <body name="right_l4" pos="0 -0.125 -0.1265" quat="0.707105 0.707108 0 0">
                            <inertial pos="-0.0027844 0.00765507 0.132724" quat="0.801021 0.0333246 -0.0340207 0.596739" mass="1.0434" diaginertia="0.0130575 0.0129033 0.00113288" />
                            <joint name="right_j4" pos="0 0 0" axis="0 0 1" limited="true" range="-2.9842 2.9842" />
                            <geom size="0.045 0.18" pos="0 0 0.14" type="cylinder" rgba="0.5 0.1 0.1 1" />
                            <body name="right_l5" pos="0 0.031 0.275" quat="0.707105 -0.707108 0 0">
                                <inertial pos="0.00620847 -0.02429 0.0755655" quat="0.405453 0.912624 0.0521875 0.000998978" mass="1.5345" diaginertia="0.00461681 0.00417719 0.00178731" />
                                <joint name="right_j5" pos="0 0 0" axis="0 0 1" limited="true" range="-2.9842 2.9842" />
                                <geom size="0.06" pos="0.01 0 0.09" rgba="0.5 0.1 0.1 1" />
                                <body name="right_l6" pos="0 -0.11 0.1053" quat="0.0616249 0.0616299 -0.704417 0.704415">
                                    <inertial pos="-4.22295e-06 0.00449037 0.0210337" quat="0.995113 0.0984675 0.000114172 0.00733621" mass="0.6293" diaginertia="0.000790748 0.000696567 0.000358388" />
                                    <joint name="right_j6" pos="0 0 0" axis="0 0 1" limited="true" range="-4.7104 4.7104" />
                                    <geom size="0.065 0.025" pos="0 0 -0.005" type="cylinder" rgba="0.5 0.1 0.1 1" />
                                    <geom size="0.029 0.05" pos="0 0 0.0495" quat="-0.500001 -0.500001 0.499999 0.499999" type="cylinder" rgba="0.5 0.1 0.1 1" />
                                    <body name="r_gripper_l_finger" pos="0.0015 5.50981e-09 0.0695" quat="0.707105 0 0 0.707108">
                                        <inertial pos="0 0.00575 0.0375667" quat="0.997118 -0.0758683 0 0" mass="0.03" diaginertia="0.0200867 0.0200867 0.02" />
                                        <joint name="r_gripper_l_finger_joint" pos="0 0 0" axis="0 1 0" type="slide" limited="true" range="0 0.020833" damping="0.7" />
                                        <geom size="0.005 0.00675 0.05635" pos="0 0.01725 0.0615" quat="0 0 0 -1" type="box" rgba="0.2 0.2 0.2 1" />
                                        <geom size="0.005 0.025 0.0085" pos="-0.005 -0.003 0.0083" quat="0 0 0 -1" type="box" rgba="0.2 0.2 0.2 1" />
                                        <geom size="0.021 0.00325 0.0185" pos="0 0.01275 0.0977" quat="0 0 0 1" type="box" rgba="0.2 0.2 0.2 1" />
                                    </body>
                                    <body name="r_gripper_r_finger" pos="-0.0015 -5.50981e-09 0.0695" quat="0.707105 0 0 0.707108">
                                        <inertial pos="0 -0.00575 0.0375667" quat="0.997118 0.0758683 0 0" mass="0.03" diaginertia="0.0200867 0.0200867 0.02" />
                                        <joint name="r_gripper_r_finger_joint" pos="0 0 0" axis="0 1 0" type="slide" limited="true" range="-0.020833 0" damping="0.7" />
                                        <geom size="0.005 0.00675 0.05635" pos="0 -0.01725 0.0615" type="box" rgba="0.2 0.2 0.2 1" />
                                        <geom size="0.005 0.025 0.0085" pos="0.005 0.003 0.0083" type="box" rgba="0.2 0.2 0.2 1" />
                                        <geom size="0.021 0.00325 0.0185" pos="0 -0.01275 0.0977" type="box" rgba="0.2 0.2 0.2 1" />
                                    </body>
                                </body>
                            </body>
                        </body>
                    </body>
                </body>
            </body>
        </body>
    </worldbody>
</mujoco>
